[2024-10-05T20:34:45.332+0700] {local_task_job_runner.py:123} INFO - ::group::Pre task execution logs
[2024-10-05T20:34:45.351+0700] {taskinstance.py:2612} INFO - Dependencies all met for dep_context=non-requeueable deps ti=<TaskInstance: talend_job_dag_Sync_Mysql_to_DWh_job.run_talend_job manual__2024-10-05T13:29:38.188987+00:00 [queued]>
[2024-10-05T20:34:45.364+0700] {taskinstance.py:2612} INFO - Dependencies all met for dep_context=requeueable deps ti=<TaskInstance: talend_job_dag_Sync_Mysql_to_DWh_job.run_talend_job manual__2024-10-05T13:29:38.188987+00:00 [queued]>
[2024-10-05T20:34:45.364+0700] {taskinstance.py:2865} INFO - Starting attempt 2 of 2
[2024-10-05T20:34:45.391+0700] {taskinstance.py:2888} INFO - Executing <Task(BashOperator): run_talend_job> on 2024-10-05 13:29:38.188987+00:00
[2024-10-05T20:34:45.397+0700] {standard_task_runner.py:72} INFO - Started process 253240 to run task
[2024-10-05T20:34:45.410+0700] {standard_task_runner.py:104} INFO - Running: ['airflow', 'tasks', 'run', 'talend_job_dag_Sync_Mysql_to_DWh_job', 'run_talend_job', 'manual__2024-10-05T13:29:38.188987+00:00', '--job-id', '32', '--raw', '--subdir', 'DAGS_FOLDER/Sync_Mysql_to_DWh_job.py', '--cfg-path', '/tmp/tmpxh5_e142']
[2024-10-05T20:34:45.412+0700] {standard_task_runner.py:105} INFO - Job 32: Subtask run_talend_job
[2024-10-05T20:34:45.508+0700] {task_command.py:467} INFO - Running <TaskInstance: talend_job_dag_Sync_Mysql_to_DWh_job.run_talend_job manual__2024-10-05T13:29:38.188987+00:00 [running]> on host linux-ip-147
[2024-10-05T20:34:45.609+0700] {abstractoperator.py:778} ERROR - Exception rendering Jinja template for task 'run_talend_job', field 'bash_command'. Template: 'sh /opt/Sync_Mysql_to_DWH_Job/run_Sync_Mysql_to_DWH_job.sh'
Traceback (most recent call last):
  File "/usr/local/lib/python3.10/dist-packages/airflow/models/abstractoperator.py", line 770, in _do_render_template_fields
    rendered_content = self.render_template(
  File "/usr/local/lib/python3.10/dist-packages/airflow/template/templater.py", line 168, in render_template
    template = jinja_env.get_template(value)
  File "/usr/lib/python3/dist-packages/jinja2/environment.py", line 997, in get_template
    return self._load_template(name, globals)
  File "/usr/lib/python3/dist-packages/jinja2/environment.py", line 958, in _load_template
    template = self.loader.load(self, name, self.make_globals(globals))
  File "/usr/lib/python3/dist-packages/jinja2/loaders.py", line 125, in load
    source, filename, uptodate = self.get_source(environment, name)
  File "/usr/lib/python3/dist-packages/jinja2/loaders.py", line 214, in get_source
    raise TemplateNotFound(template)
jinja2.exceptions.TemplateNotFound: sh /opt/Sync_Mysql_to_DWH_Job/run_Sync_Mysql_to_DWH_job.sh
[2024-10-05T20:34:45.612+0700] {taskinstance.py:3310} ERROR - Task failed with exception
Traceback (most recent call last):
  File "/usr/local/lib/python3.10/dist-packages/airflow/models/taskinstance.py", line 273, in _run_raw_task
    TaskInstance._execute_task_with_callbacks(
  File "/usr/local/lib/python3.10/dist-packages/airflow/models/taskinstance.py", line 3114, in _execute_task_with_callbacks
    task_orig = self.render_templates(context=context, jinja_env=jinja_env)
  File "/usr/local/lib/python3.10/dist-packages/airflow/models/taskinstance.py", line 3533, in render_templates
    original_task.render_template_fields(context, jinja_env)
  File "/usr/local/lib/python3.10/dist-packages/airflow/models/baseoperator.py", line 1419, in render_template_fields
    self._do_render_template_fields(self, self.template_fields, context, jinja_env, set())
  File "/usr/local/lib/python3.10/dist-packages/airflow/models/abstractoperator.py", line 770, in _do_render_template_fields
    rendered_content = self.render_template(
  File "/usr/local/lib/python3.10/dist-packages/airflow/template/templater.py", line 168, in render_template
    template = jinja_env.get_template(value)
  File "/usr/lib/python3/dist-packages/jinja2/environment.py", line 997, in get_template
    return self._load_template(name, globals)
  File "/usr/lib/python3/dist-packages/jinja2/environment.py", line 958, in _load_template
    template = self.loader.load(self, name, self.make_globals(globals))
  File "/usr/lib/python3/dist-packages/jinja2/loaders.py", line 125, in load
    source, filename, uptodate = self.get_source(environment, name)
  File "/usr/lib/python3/dist-packages/jinja2/loaders.py", line 214, in get_source
    raise TemplateNotFound(template)
jinja2.exceptions.TemplateNotFound: sh /opt/Sync_Mysql_to_DWH_Job/run_Sync_Mysql_to_DWH_job.sh
[2024-10-05T20:34:45.622+0700] {logging_mixin.py:190} INFO - Task instance in failure state
[2024-10-05T20:34:45.623+0700] {logging_mixin.py:190} INFO - Task start:2024-10-05 13:34:45.351940+00:00 end:2024-10-05 13:34:45.620976+00:00 duration:0.269036
[2024-10-05T20:34:45.624+0700] {logging_mixin.py:190} INFO - Task:<Task(BashOperator): run_talend_job> dag:<DAG: talend_job_dag_Sync_Mysql_to_DWh_job> dagrun:<DagRun talend_job_dag_Sync_Mysql_to_DWh_job @ 2024-10-05 13:29:38.188987+00:00: manual__2024-10-05T13:29:38.188987+00:00, state:running, queued_at: 2024-10-05 13:29:38.229770+00:00. externally triggered: True>
[2024-10-05T20:34:45.624+0700] {logging_mixin.py:190} INFO - Failure caused by sh /opt/Sync_Mysql_to_DWH_Job/run_Sync_Mysql_to_DWH_job.sh
[2024-10-05T20:34:45.625+0700] {taskinstance.py:1225} INFO - Marking task as FAILED. dag_id=talend_job_dag_Sync_Mysql_to_DWh_job, task_id=run_talend_job, run_id=manual__2024-10-05T13:29:38.188987+00:00, execution_date=20241005T132938, start_date=20241005T133445, end_date=20241005T133445
[2024-10-05T20:34:45.626+0700] {taskinstance.py:1563} INFO - Executing callback at index 0: notify_failure_callback
[2024-10-05T20:34:46.639+0700] {Sync_Mysql_to_DWh_job.py:37} INFO - Gửi thành công: {'ok': True, 'result': {'message_id': 228, 'from': {'id': 7156222811, 'is_bot': True, 'first_name': 'etlbot', 'username': 'talend_etl_bot'}, 'chat': {'id': -4560962078, 'title': 'notify_talend_etl', 'type': 'group', 'all_members_are_administrators': True}, 'date': 1728135286, 'text': 'Job Talend đã thất bại!\nTask: run_talend_job\nExecution Date: 2024-10-05 13:29:38.188987+00:00\nLỗi: sh /opt/Sync_Mysql_to_DWH_Job/run_Sync_Mysql_to_DWH_job.sh\nThời gian bắt đầu: 2024-10-05 13:34:45.351940+00:00\nThời gian kết thúc: 2024-10-05 13:34:45.620976+00:00\nLog URL: http://localhost:8080/dags/talend_job_dag_Sync_Mysql_to_DWh_job/grid?dag_run_id=manual__2024-10-05T13%3A29%3A38.188987%2B00%3A00&task_id=run_talend_job&base_date=2024-10-05T13%3A29%3A38%2B0000&tab=logs'}}
[2024-10-05T20:34:46.663+0700] {taskinstance.py:340} INFO - ::group::Post task execution logs
[2024-10-05T20:34:46.664+0700] {standard_task_runner.py:124} ERROR - Failed to execute job 32 for task run_talend_job (sh /opt/Sync_Mysql_to_DWH_Job/run_Sync_Mysql_to_DWH_job.sh; 253240)
Traceback (most recent call last):
  File "/usr/local/lib/python3.10/dist-packages/airflow/task/task_runner/standard_task_runner.py", line 117, in _start_by_fork
    ret = args.func(args, dag=self.dag)
  File "/usr/local/lib/python3.10/dist-packages/airflow/cli/cli_config.py", line 49, in command
    return func(*args, **kwargs)
  File "/usr/local/lib/python3.10/dist-packages/airflow/utils/cli.py", line 115, in wrapper
    return f(*args, **kwargs)
  File "/usr/local/lib/python3.10/dist-packages/airflow/cli/commands/task_command.py", line 483, in task_run
    task_return_code = _run_task_by_selected_method(args, _dag, ti)
  File "/usr/local/lib/python3.10/dist-packages/airflow/cli/commands/task_command.py", line 256, in _run_task_by_selected_method
    return _run_raw_task(args, ti)
  File "/usr/local/lib/python3.10/dist-packages/airflow/cli/commands/task_command.py", line 341, in _run_raw_task
    return ti._run_raw_task(
  File "/usr/local/lib/python3.10/dist-packages/airflow/utils/session.py", line 97, in wrapper
    return func(*args, session=session, **kwargs)
  File "/usr/local/lib/python3.10/dist-packages/airflow/models/taskinstance.py", line 3004, in _run_raw_task
    return _run_raw_task(
  File "/usr/local/lib/python3.10/dist-packages/airflow/models/taskinstance.py", line 273, in _run_raw_task
    TaskInstance._execute_task_with_callbacks(
  File "/usr/local/lib/python3.10/dist-packages/airflow/models/taskinstance.py", line 3114, in _execute_task_with_callbacks
    task_orig = self.render_templates(context=context, jinja_env=jinja_env)
  File "/usr/local/lib/python3.10/dist-packages/airflow/models/taskinstance.py", line 3533, in render_templates
    original_task.render_template_fields(context, jinja_env)
  File "/usr/local/lib/python3.10/dist-packages/airflow/models/baseoperator.py", line 1419, in render_template_fields
    self._do_render_template_fields(self, self.template_fields, context, jinja_env, set())
  File "/usr/local/lib/python3.10/dist-packages/airflow/models/abstractoperator.py", line 770, in _do_render_template_fields
    rendered_content = self.render_template(
  File "/usr/local/lib/python3.10/dist-packages/airflow/template/templater.py", line 168, in render_template
    template = jinja_env.get_template(value)
  File "/usr/lib/python3/dist-packages/jinja2/environment.py", line 997, in get_template
    return self._load_template(name, globals)
  File "/usr/lib/python3/dist-packages/jinja2/environment.py", line 958, in _load_template
    template = self.loader.load(self, name, self.make_globals(globals))
  File "/usr/lib/python3/dist-packages/jinja2/loaders.py", line 125, in load
    source, filename, uptodate = self.get_source(environment, name)
  File "/usr/lib/python3/dist-packages/jinja2/loaders.py", line 214, in get_source
    raise TemplateNotFound(template)
jinja2.exceptions.TemplateNotFound: sh /opt/Sync_Mysql_to_DWH_Job/run_Sync_Mysql_to_DWH_job.sh
[2024-10-05T20:34:46.710+0700] {local_task_job_runner.py:266} INFO - Task exited with return code 1
[2024-10-05T20:34:46.752+0700] {taskinstance.py:3900} INFO - 0 downstream tasks scheduled from follow-on schedule check
[2024-10-05T20:34:46.763+0700] {local_task_job_runner.py:245} INFO - ::endgroup::
